<?xml version="1.0"?>
<robot name="DoublePendulum4">

  <material name="black">
    <color rgba="0 0 0 1" />
  </material>
  <material name="MITred">
    <color rgba=".6 .2 .2 1" />
  </material>

  <link name="upper_arm">
    <inertial>
      <origin xyz="0 0 -1" rpy="0 0 0" />
      <mass value="1" />
      <inertia ixx="0" ixy="0" ixz="0" iyy="0" iyz="0" izz="0"/> 
    </inertial>
    <visual>
      <origin xyz="0 0 -1"/>
      <geometry>
        <sphere radius=".1"/>
      </geometry>
      <material name="MITred" />
    </visual>
    <visual>
      <origin xyz="0 0 -.5" rpy="0 0 0" />
      <geometry>
          <cylinder length="1" radius=".01" />
      </geometry>
      <material name="black" />
    </visual>
  </link>

  <link name="lower_arm">
    <inertial>
      <origin xyz="0 0 -1" rpy="0 0 0" />
      <mass value="1" />
      <inertia ixx="0" ixy="0" ixz="0" iyy="0" iyz="0" izz="0"/> 
    </inertial>
    <visual>
      <origin xyz="0 0 -1"/>
      <geometry>
        <sphere radius=".1"/>
      </geometry>
      <material name="MITred" />
    </visual>
     <visual>
      <origin xyz="0 0 -.5" rpy="0 0 0" />
      <geometry>
          <cylinder length="1" radius=".01" />
      </geometry>
      <material name="black" />
    </visual>
  </link>

  <joint name="shoulder" type="revolute">
    <parent link="world"/>
    <child link="upper_arm" />
    <axis xyz="0 1 0" />
    <origin xyz="0 0 0" />
  </joint>
  <!-- add an actuator for the shoulder -->
  <transmission type="SimpleTransmission" name="shoulder_trans">
    <actuator name="shoulder_act" />
    <joint name="shoulder" />
  </transmission>

  <joint name="elbow" type="revolute">
    <parent link="upper_arm"/>
    <child link="lower_arm" /> 
    <axis xyz="0 1 0" />
    <origin xyz="0 0 -1" />
  </joint>
  <transmission type="SimpleTransmission" name="elbow_trans">
    <actuator name="elbow_act" />
    <joint name="elbow" />
  </transmission>

</robot>